Workbook

Sheet Raw Data
A1: Employee ID | B1: Name | C1: Department | D1: Country | E1: Salary | F1: Date of Joining | G1: Performance Rating | H1: Gender | I1: Email
A2: EMP1000 | C2: Finance | E2: N/A | G2: 2 | H2: Unknown | I2: invalid_email
A3: EMP1001 | B3: Eve Adams | C3: HR | D3: Germany | E3: 54255 | F3: 42015 | G3: 1 | H3: Other | I3: user106@example.com
A4: EMP1002 | B4: Alice Brown | C4: Finance | D4: Germany | E4: 63184 | F4: 42022 | G4: 2 | I4: user176@example.com
A5: EMP1003 | B5: John Doe | C5: Sales | D5: USA | E5: 94406 | F5: 42029 | G5: 1 | H5: Male | I5: user168@example.com
A6: EMP1004 | B6: Jane Smith | C6: Sales | D6: Germany | E6: 64120 | F6: 42036 | G6: 1 | H6: Male | I6: user49@example.com
A7: EMP1005 | B7: Alice Brown | C7: IT | D7: India | E7: 78421 | F7: 42043 | G7: 2 | H7: Female | I7: user24@example.com
A8: EMP1006 | B8: Sam Wilson | C8: Sales | E8: 67721 | F8: 42050 | H8: Male | I8: user168@example.com
A9: EMP1007 | B9: Chris Lee | C9: Marketing | E9: 35364 | F9: 42057 | G9: 2 | H9: Other | I9: user26@example.com
A10: EMP1008 | B10: Alice Brown | C10: IT | D10: Germany | E10: 97881 | F10: 42064 | H10: Female | I10: user25@example.com
A11: EMP1009 | B11: Chris Lee | C11: HR | D11: UK | E11: 91846 | F11: 42071 | H11: Male | I11: user153@example.com
A12: EMP1010 | B12: Sam Wilson | C12: Finance | D12: UK | E12: 64247 | F12: 42078 | G12: 1 | H12: Female | I12: user18@example.com
A13: EMP1011 | B13: Sam Wilson | C13: IT | D13: USA | E13: 91180 | F13: 42085 | G13: 5 | H13: Male | I13: user1@example.com
A14: EMP1012 | B14: Bob Johnson | C14: Sales | E14: 96418 | F14: 42092 | G14: 5 | H14: Male | I14: user106@example.com
A15: EMP1013 | B15: Sam Wilson | D15: India | E15: 62158 | F15: 42099 | G15: 4 | I15: user180@example.com
A16: EMP1014 | B16: Jane Smith | C16: HR | E16: 59894 | F16: 42106 | G16: 2 | H16: Male | I16: user184@example.com
A17: EMP1015 | C17: IT | D17: India | E17: 92443 | F17: 42113 | G17: 3 | H17: Other | I17: user3@example.com
A18: EMP1016 | B18: Bob Johnson | D18: Germany | E18: 90271 | F18: 42120 | I18: user64@example.com
A19: EMP1017 | B19: Jane Smith | C19: Finance | D19: Australia | E19: 41341 | F19: 42127 | G19: 1 | H19: Other | I19: user38@example.com
A20: EMP1018 | B20: Alice Brown | C20: Finance | D20: UK | E20: 73602 | F20: 42134 | I20: user96@example.com
A21: EMP1019 | B21: Eve Adams | D21: India | E21: 67531 | F21: 42141 | G21: 5 | H21: Female | I21: user151@example.com
A22: EMP1020 | B22: Jane Smith | C22: HR | D22: USA | E22: N/A | F22: 42148 | G22: 2 | H22: Other | I22: user200@example.com
A23: EMP1021 | B23: Jane Smith | C23: HR | E23: 98922 | F23: 42155 | G23: 4 | I23: user77@example.com
A24: EMP1022 | B24: Eve Adams | C24: Finance | D24: India | E24: 38333 | F24: 42162 | G24: 5 | I24: user128@example.com
A25: EMP1023 | B25: Alice Brown | C25: Marketing | D25: UK | E25: 36515 | F25: 42169 | G25: 3 | H25: Male | I25: user149@example.com
A26: EMP1024 | B26: Sam Wilson | C26: Finance | E26: 91005 | F26: 42176 | G26: 1 | H26: Other | I26: user122@example.com
A27: EMP1025 | B27: Chris Lee | E27: 52272 | F27: 42183 | G27: 3 | I27: user41@example.com
A28: EMP1026 | B28: Eve Adams | C28: Sales | D28: Germany | E28: 76518 | F28: 42190 | G28: 2 | H28: Female | I28: user68@example.com
A29: EMP1027 | B29: Alice Brown | C29: IT | D29: UK | E29: 41448 | F29: 42197 | G29: 3 | H29: Other | I29: user103@example.com
A30: EMP1028 | B30: John Doe | C30: HR | D30: UK | E30: 49282 | F30: 42204 | G30: 2 | H30: Female | I30: user135@example.com
A31: EMP1029 | B31: Bob Johnson | C31: Marketing | D31: UK | E31: 92959 | F31: 42211 | G31: 5 | I31: user83@example.com
A32: EMP1030 | C32: Marketing | E32: 92259 | G32: 1 | H32: Unknown | I32: user109@example.com
A33: EMP1031 | B33: Eve Adams | C33: HR | D33: Germany | E33: 92299 | F33: 42225 | G33: 3 | H33: Male | I33: user143@example.com
A34: EMP1032 | B34: Sam Wilson | C34: HR | E34: 95586 | F34: 42232 | G34: 3 | H34: Other | I34: user190@example.com
A35: EMP1033 | B35: Chris Lee | D35: USA | E35: 95367 | F35: 42239 | H35: Male | I35: user136@example.com
A36: EMP1034 | B36: John Doe | C36: Sales | D36: Australia | E36: 79549 | F36: 42246 | G36: 3 | I36: user198@example.com
A37: EMP1035 | B37: Alice Brown | D37: UK | E37: 54463 | F37: 42253 | G37: 4 | H37: Male | I37: invalid_email
A38: EMP1036 | B38: Alice Brown | C38: IT | D38: USA | E38: 89781 | F38: 42260 | H38: Female | I38: user31@example.com
A39: EMP1037 | B39: Alice Brown | C39: HR | E39: 64796 | F39: 42267 | H39: Other | I39: user98@example.com
A40: EMP1038 | B40: John Doe | C40: Marketing | D40: UK | E40: 52093 | F40: 42274 | G40: 5 | I40: user154@example.com
...

Sheet Sheet2
A1: Row Labels | B1: Sum of PerformanceRating
A2: Finance | B2: 58
A3: HR | B3: 66
A4: IT | B4: 74
A5: Marketing | B5: 97
A6: Sales | B6: 72
A7: Unknown | B7: 67
A8: (blank)
A9: Grand Total | B9: 434

Sheet Employee_Cleaned
A1: EmployeeID | B1: Name | C1: FirstName | D1: LastName | E1: CleanedName | F1: Department | G1: Country | H1: Salary | I1: Date | J1: Experience | K1: Joining Year | L1: Joining month | M1: Joining weekday | N1: Current_Date_Time | O1: PerformanceRating | P1: Gender | Q1: Email
A2: EMP1011 | B2: SamWilson | C2: Sam | D2: Wilson | E2: =TRIM(B2) -> SamWilson | F2: IT | G2: USA | H2: 91180 | I2: 42085 | J2: =IF(I2="Unknown","Unknown",DATEDIF(I2,TODAY(),"Y")) -> 10 | K2: =IF(I2="Unknown","Unknown",YEAR(I2)) -> 2015 | L2: =IF(I2="Unknown","Unknown",MONTH(I2)) -> 3 | M2: =IF(I2="Unknown","Unknown",WEEKDAY(I2)) -> 1 | N2: =NOW() -> 46090.857 | O2: 5 | P2: Male | Q2: user1@example.com
A3: EMP1012 | B3: BobJohnson | C3: Bob | D3: Johnson | E3: =TRIM(B3) -> BobJohnson | F3: Sales | G3: Unknown | H3: 96418 | I3: 42092 | J3: =IF(I3="Unknown","Unknown",DATEDIF(I3,TODAY(),"Y")) -> 10 | K3: =IF(I3="Unknown","Unknown",YEAR(I3)) -> 2015 | L3: =IF(I3="Unknown","Unknown",MONTH(I3)) -> 3 | M3: =IF(I3="Unknown","Unknown",WEEKDAY(I3)) -> 1 | N3: =NOW() -> 46090.857 | O3: 5 | P3: Male | Q3: user106@example.com
A4: EMP1019 | B4: EveAdams | C4: Eve | D4: Adams | E4: =TRIM(B4) -> EveAdams | F4: Unknown | G4: India | H4: 67531 | I4: 42141 | J4: =IF(I4="Unknown","Unknown",DATEDIF(I4,TODAY(),"Y")) -> 10 | K4: =IF(I4="Unknown","Unknown",YEAR(I4)) -> 2015 | L4: =IF(I4="Unknown","Unknown",MONTH(I4)) -> 5 | M4: =IF(I4="Unknown","Unknown",WEEKDAY(I4)) -> 1 | N4: =NOW() -> 46090.857 | O4: 5 | P4: Female | Q4: user151@example.com
A5: EMP1022 | B5: EveAdams | C5: Eve | D5: Adams | E5: =TRIM(B5) -> EveAdams | F5: Finance | G5: India | H5: 38333 | I5: 42162 | J5: =IF(I5="Unknown","Unknown",DATEDIF(I5,TODAY(),"Y")) -> 10 | K5: =IF(I5="Unknown","Unknown",YEAR(I5)) -> 2015 | L5: =IF(I5="Unknown","Unknown",MONTH(I5)) -> 6 | M5: =IF(I5="Unknown","Unknown",WEEKDAY(I5)) -> 1 | N5: =NOW() -> 46090.857 | O5: 5 | P5: Unknown | Q5: user128@example.com
A6: EMP1029 | B6: BobJohnson | C6: Bob | D6: Johnson | E6: =TRIM(B6) -> BobJohnson | F6: Marketing | G6: UK | H6: 92959 | I6: 42211 | J6: =IF(I6="Unknown","Unknown",DATEDIF(I6,TODAY(),"Y")) -> 10 | K6: =IF(I6="Unknown","Unknown",YEAR(I6)) -> 2015 | L6: =IF(I6="Unknown","Unknown",MONTH(I6)) -> 7 | M6: =IF(I6="Unknown","Unknown",WEEKDAY(I6)) -> 1 | N6: =NOW() -> 46090.857 | O6: 5 | P6: Unknown | Q6: user83@example.com
A7: EMP1038 | B7: JohnDoe | C7: John | D7: Doe | E7: =TRIM(B7) -> JohnDoe | F7: Marketing | G7: UK | H7: 52093 | I7: 42274 | J7: =IF(I7="Unknown","Unknown",DATEDIF(I7,TODAY(),"Y")) -> 10 | K7: =IF(I7="Unknown","Unknown",YEAR(I7)) -> 2015 | L7: =IF(I7="Unknown","Unknown",MONTH(I7)) -> 9 | M7: =IF(I7="Unknown","Unknown",WEEKDAY(I7)) -> 1 | N7: =NOW() -> 46090.857 | O7: 5 | P7: Unknown | Q7: user154@example.com
A8: EMP1049 | B8: EveAdams | C8: Eve | D8: Adams | E8: =TRIM(B8) -> EveAdams | F8: HR | G8: Germany | H8: 78720 | I8: 42351 | J8: =IF(I8="Unknown","Unknown",DATEDIF(I8,TODAY(),"Y")) -> 10 | K8: =IF(I8="Unknown","Unknown",YEAR(I8)) -> 2015 | L8: =IF(I8="Unknown","Unknown",MONTH(I8)) -> 12 | M8: =IF(I8="Unknown","Unknown",WEEKDAY(I8)) -> 1 | N8: =NOW() -> 46090.857 | O8: 5 | P8: Female | Q8: user89@example.com
A9: EMP1051 | B9: SamWilson | C9: Sam | D9: Wilson | E9: =TRIM(B9) -> SamWilson | F9: Sales | G9: India | H9: 39423 | I9: 42365 | J9: =IF(I9="Unknown","Unknown",DATEDIF(I9,TODAY(),"Y")) -> 10 | K9: =IF(I9="Unknown","Unknown",YEAR(I9)) -> 2015 | L9: =IF(I9="Unknown","Unknown",MONTH(I9)) -> 12 | M9: =IF(I9="Unknown","Unknown",WEEKDAY(I9)) -> 1 | N9: =NOW() -> 46090.857 | O9: 5 | P9: Unknown | Q9: user59@example.com
A10: EMP1054 | B10: BobJohnson | C10: Bob | D10: Johnson | E10: =TRIM(B10) -> BobJohnson | F10: Marketing | G10: UK | H10: 75633 | I10: 42386 | J10: =IF(I10="Unknown","Unknown",DATEDIF(I10,TODAY(),"Y")) -> 10 | K10: =IF(I10="Unknown","Unknown",YEAR(I10)) -> 2016 | L10: =IF(I10="Unknown","Unknown",MONTH(I10)) -> 1 | M10: =IF(I10="Unknown","Unknown",WEEKDAY(I10)) -> 1 | N10: =NOW() -> 46090.857 | O10: 5 | P10: Other | Q10: user92@example.com
A11: EMP1055 | B11: ChrisLee | C11: Chris | D11: Lee | E11: =TRIM(B11) -> ChrisLee | F11: Unknown | G11: USA | H11: 74815 | I11: 42393 | J11: =IF(I11="Unknown","Unknown",DATEDIF(I11,TODAY(),"Y")) -> 10 | K11: =IF(I11="Unknown","Unknown",YEAR(I11)) -> 2016 | L11: =IF(I11="Unknown","Unknown",MONTH(I11)) -> 1 | M11: =IF(I11="Unknown","Unknown",WEEKDAY(I11)) -> 1 | N11: =NOW() -> 46090.857 | O11: 5 | P11: Female | Q11: user50@example.com
A12: EMP1058 | B12: SamWilson | C12: Sam | D12: Wilson | E12: =TRIM(B12) -> SamWilson | F12: Marketing | G12: Unknown | H12: 84924 | I12: 42414 | J12: =IF(I12="Unknown","Unknown",DATEDIF(I12,TODAY(),"Y")) -> 10 | K12: =IF(I12="Unknown","Unknown",YEAR(I12)) -> 2016 | L12: =IF(I12="Unknown","Unknown",MONTH(I12)) -> 2 | M12: =IF(I12="Unknown","Unknown",WEEKDAY(I12)) -> 1 | N12: =NOW() -> 46090.857 | O12: 5 | P12: Male | Q12: user150@example.com
A13: EMP1060 | B13: Unknown | C13: Unknown | D13: Unknown | E13: =TRIM(B13) -> Unknown | F13: Marketing | G13: Germany | H13: 66281 | I13: Unknown | J13: =IF(I13="Unknown","Unknown",DATEDIF(I13,TODAY(),"Y")) -> Unknown | K13: =IF(I13="Unknown","Unknown",YEAR(I13)) -> Unknown | L13: =IF(I13="Unknown","Unknown",MONTH(I13)) -> Unknown | M13: =IF(I13="Unknown","Unknown",WEEKDAY(I13)) -> Unknown | N13: =NOW() -> 46090.857 | O13: 5 | P13: Unknown | Q13: user112@example.com
A14: EMP1062 | B14: ChrisLee | C14: Chris | D14: Lee | E14: =TRIM(B14) -> ChrisLee | F14: IT | G14: UK | H14: 97981 | I14: 42442 | J14: =IF(I14="Unknown","Unknown",DATEDIF(I14,TODAY(),"Y")) -> 9 | K14: =IF(I14="Unknown","Unknown",YEAR(I14)) -> 2016 | L14: =IF(I14="Unknown","Unknown",MONTH(I14)) -> 3 | M14: =IF(I14="Unknown","Unknown",WEEKDAY(I14)) -> 1 | N14: =NOW() -> 46090.857 | O14: 5 | P14: Female | Q14: user71@example.com
A15: EMP1070 | B15: EveAdams | C15: Eve | D15: Adams | E15: =TRIM(B15) -> EveAdams | F15: Sales | G15: Australia | H15: 69952 | I15: 42498 | J15: =IF(I15="Unknown","Unknown",DATEDIF(I15,TODAY(),"Y")) -> 9 | K15: =IF(I15="Unknown","Unknown",YEAR(I15)) -> 2016 | L15: =IF(I15="Unknown","Unknown",MONTH(I15)) -> 5 | M15: =IF(I15="Unknown","Unknown",WEEKDAY(I15)) -> 1 | N15: =NOW() -> 46090.857 | O15: 5 | P15: Female | Q15: Unknown
A16: EMP1085 | B16: ChrisLee | C16: Chris | D16: Lee | E16: =TRIM(B16) -> ChrisLee | F16: Finance | G16: Unknown | H16: 35163 | I16: 42603 | J16: =IF(I16="Unknown","Unknown",DATEDIF(I16,TODAY(),"Y")) -> 9 | K16: =IF(I16="Unknown","Unknown",YEAR(I16)) -> 2016 | L16: =IF(I16="Unknown","Unknown",MONTH(I16)) -> 8 | M16: =IF(I16="Unknown","Unknown",WEEKDAY(I16)) -> 1 | N16: =NOW() -> 46090.857 | O16: 5 | P16: Other | Q16: user197@example.com
A17: EMP1092 | B17: JaneSmith | C17: Jane | D17: Smith | E17: =TRIM(B17) -> JaneSmith | F17: IT | G17: Unknown | H17: 80588 | I17: 42652 | J17: =IF(I17="Unknown","Unknown",DATEDIF(I17,TODAY(),"Y")) -> 9 | K17: =IF(I17="Unknown","Unknown",YEAR(I17)) -> 2016 | L17: =IF(I17="Unknown","Unknown",MONTH(I17)) -> 10 | M17: =IF(I17="Unknown","Unknown",WEEKDAY(I17)) -> 1 | N17: =NOW() -> 46090.857 | O17: 5 | P17: Male | Q17: user98@example.com
A18: EMP1103 | B18: AliceBrown | C18: Alice | D18: Brown | E18: =TRIM(B18) -> AliceBrown | F18: Marketing | G18: Unknown | H18: 79145 | I18: 42729 | J18: =IF(I18="Unknown","Unknown",DATEDIF(I18,TODAY(),"Y")) -> 9 | K18: =IF(I18="Unknown","Unknown",YEAR(I18)) -> 2016 | L18: =IF(I18="Unknown","Unknown",MONTH(I18)) -> 12 | M18: =IF(I18="Unknown","Unknown",WEEKDAY(I18)) -> 1 | N18: =NOW() -> 46090.857 | O18: 5 | P18: Other | Q18: user20@example.com
A19: EMP1111 | B19: ChrisLee | C19: Chris | D19: Lee | E19: =TRIM(B19) -> ChrisLee | F19: IT | G19: USA | H19: 34306 | I19: 42785 | J19: =IF(I19="Unknown","Unknown",DATEDIF(I19,TODAY(),"Y")) -> 9 | K19: =IF(I19="Unknown","Unknown",YEAR(I19)) -> 2017 | L19: =IF(I19="Unknown","Unknown",MONTH(I19)) -> 2 | M19: =IF(I19="Unknown","Unknown",WEEKDAY(I19)) -> 1 | N19: =NOW() -> 46090.857 | O19: 5 | P19: Female | Q19: user192@example.com
A20: EMP1116 | B20: BobJohnson | C20: Bob | D20: Johnson | E20: =TRIM(B20) -> BobJohnson | F20: Marketing | G20: Australia | H20: 38837 | I20: 42820 | J20: =IF(I20="Unknown","Unknown",DATEDIF(I20,TODAY(),"Y")) -> 8 | K20: =IF(I20="Unknown","Unknown",YEAR(I20)) -> 2017 | L20: =IF(I20="Unknown","Unknown",MONTH(I20)) -> 3 | M20: =IF(I20="Unknown","Unknown",WEEKDAY(I20)) -> 1 | N20: =NOW() -> 46090.857 | O20: 5 | P20: Female | Q20: user192@example.com
A21: EMP1120 | B21: Unknown | C21: Unknown | D21: Unknown | E21: =TRIM(B21) -> Unknown | F21: IT | G21: USA | H21: 66281 | I21: Unknown | J21: =IF(I21="Unknown","Unknown",DATEDIF(I21,TODAY(),"Y")) -> Unknown | K21: =IF(I21="Unknown","Unknown",YEAR(I21)) -> Unknown | L21: =IF(I21="Unknown","Unknown",MONTH(I21)) -> Unknown | M21: =IF(I21="Unknown","Unknown",WEEKDAY(I21)) -> Unknown | N21: =NOW() -> 46090.857 | O21: 5 | P21: Unknown | Q21: user101@example.com
A22: EMP1123 | B22: JaneSmith | C22: Jane | D22: Smith | E22: =TRIM(B22) -> JaneSmith | F22: Unknown | G22: Germany | H22: 30357 | I22: 42869 | J22: =IF(I22="Unknown","Unknown",DATEDIF(I22,TODAY(),"Y")) -> 8 | K22: =IF(I22="Unknown","Unknown",YEAR(I22)) -> 2017 | L22: =IF(I22="Unknown","Unknown",MONTH(I22)) -> 5 | M22: =IF(I22="Unknown","Unknown",WEEKDAY(I22)) -> 1 | N22: =NOW() -> 46090.857 | O22: 5 | P22: Male | Q22: user145@example.com
A23: EMP1125 | B23: JohnDoe | C23: John | D23: Doe | E23: =TRIM(B23) -> JohnDoe | F23: Finance | G23: Unknown | H23: 90019 | I23: 42883 | J23: =IF(I23="Unknown","Unknown",DATEDIF(I23,TODAY(),"Y")) -> 8 | K23: =IF(I23="Unknown","Unknown",YEAR(I23)) -> 2017 | L23: =IF(I23="Unknown","Unknown",MONTH(I23)) -> 5 | M23: =IF(I23="Unknown","Unknown",WEEKDAY(I23)) -> 1 | N23: =NOW() -> 46090.857 | O23: 5 | P23: Unknown | Q23: user52@example.com
A24: EMP1141 | B24: JaneSmith | C24: Jane | D24: Smith | E24: =TRIM(B24) -> JaneSmith | F24: Marketing | G24: USA | H24: 66882 | I24: 42995 | J24: =IF(I24="Unknown","Unknown",DATEDIF(I24,TODAY(),"Y")) -> 8 | K24: =IF(I24="Unknown","Unknown",YEAR(I24)) -> 2017 | L24: =IF(I24="Unknown","Unknown",MONTH(I24)) -> 9 | M24: =IF(I24="Unknown","Unknown",WEEKDAY(I24)) -> 1 | N24: =NOW() -> 46090.857 | O24: 5 | P24: Other | Q24: user103@example.com
A25: EMP1145 | B25: SamWilson | C25: Sam | D25: Wilson | E25: =TRIM(B25) -> SamWilson | F25: Sales | G25: Australia | H25: 35627 | I25: 43023 | J25: =IF(I25="Unknown","Unknown",DATEDIF(I25,TODAY(),"Y")) -> 8 | K25: =IF(I25="Unknown","Unknown",YEAR(I25)) -> 2017 | L25: =IF(I25="Unknown","Unknown",MONTH(I25)) -> 10 | M25: =IF(I25="Unknown","Unknown",WEEKDAY(I25)) -> 1 | N25: =NOW() -> 46090.857 | O25: 5 | P25: Female | Q25: user188@example.com
A26: EMP1149 | B26: SamWilson | C26: Sam | D26: Wilson | E26: =TRIM(B26) -> SamWilson | F26: Marketing | G26: India | H26: 98475 | I26: 43051 | J26: =IF(I26="Unknown","Unknown",DATEDIF(I26,TODAY(),"Y")) -> 8 | K26: =IF(I26="Unknown","Unknown",YEAR(I26)) -> 2017 | L26: =IF(I26="Unknown","Unknown",MONTH(I26)) -> 11 | M26: =IF(I26="Unknown","Unknown",WEEKDAY(I26)) -> 1 | N26: =NOW() -> 46090.857 | O26: 5 | P26: Other | Q26: user30@example.com
A27: EMP1013 | B27: SamWilson | C27: Sam | D27: Wilson | E27: =TRIM(B27) -> SamWilson | F27: Unknown | G27: India | H27: 62158 | I27: 42099 | J27: =IF(I27="Unknown","Unknown",DATEDIF(I27,TODAY(),"Y")) -> 10 | K27: =IF(I27="Unknown","Unknown",YEAR(I27)) -> 2015 | L27: =IF(I27="Unknown","Unknown",MONTH(I27)) -> 4 | M27: =IF(I27="Unknown","Unknown",WEEKDAY(I27)) -> 1 | N27: =NOW() -> 46090.857 | O27: 4 | P27: Unknown | Q27: user180@example.com
A28: EMP1021 | B28: JaneSmith | C28: Jane | D28: Smith | E28: =TRIM(B28) -> JaneSmith | F28: HR | G28: Unknown | H28: 98922 | I28: 42155 | J28: =IF(I28="Unknown","Unknown",DATEDIF(I28,TODAY(),"Y")) -> 10 | K28: =IF(I28="Unknown","Unknown",YEAR(I28)) -> 2015 | L28: =IF(I28="Unknown","Unknown",MONTH(I28)) -> 5 | M28: =IF(I28="Unknown","Unknown",WEEKDAY(I28)) -> 1 | N28: =NOW() -> 46090.857 | O28: 4 | P28: Unknown | Q28: user77@example.com
A29: EMP1035 | B29: AliceBrown | C29: Alice | D29: Brown | E29: =TRIM(B29) -> AliceBrown | F29: Unknown | G29: UK | H29: 54463 | I29: 42253 | J29: =IF(I29="Unknown","Unknown",DATEDIF(I29,TODAY(),"Y")) -> 10 | K29: =IF(I29="Unknown","Unknown",YEAR(I29)) -> 2015 | L29: =IF(I29="Unknown","Unknown",MONTH(I29)) -> 9 | M29: =IF(I29="Unknown","Unknown",WEEKDAY(I29)) -> 1 | N29: =NOW() -> 46090.857 | O29: 4 | P29: Male | Q29: Unknown
A30: EMP1040 | B30: BobJohnson | C30: Bob | D30: Johnson | E30: =TRIM(B30) -> BobJohnson | F30: Finance | G30: UK | H30: 66281 | I30: Unknown | J30: =IF(I30="Unknown","Unknown",DATEDIF(I30,TODAY(),"Y")) -> Unknown | K30: =IF(I30="Unknown","Unknown",YEAR(I30)) -> Unknown | L30: =IF(I30="Unknown","Unknown",MONTH(I30)) -> Unknown | M30: =IF(I30="Unknown","Unknown",WEEKDAY(I30)) -> Unknown | N30: =NOW() -> 46090.857 | O30: 4 | P30: Female | Q30: user89@example.com
A31: EMP1047 | B31: ChrisLee | C31: Chris | D31: Lee | E31: =TRIM(B31) -> ChrisLee | F31: HR | G31: India | H31: 58245 | I31: 42337 | J31: =IF(I31="Unknown","Unknown",DATEDIF(I31,TODAY(),"Y")) -> 10 | K31: =IF(I31="Unknown","Unknown",YEAR(I31)) -> 2015 | L31: =IF(I31="Unknown","Unknown",MONTH(I31)) -> 11 | M31: =IF(I31="Unknown","Unknown",WEEKDAY(I31)) -> 1 | N31: =NOW() -> 46090.857 | O31: 4 | P31: Unknown | Q31: user43@example.com
A32: EMP1065 | B32: SamWilson | C32: Sam | D32: Wilson | E32: =TRIM(B32) -> SamWilson | F32: Finance | G32: India | H32: 33468 | I32: 42463 | J32: =IF(I32="Unknown","Unknown",DATEDIF(I32,TODAY(),"Y")) -> 9 | K32: =IF(I32="Unknown","Unknown",YEAR(I32)) -> 2016 | L32: =IF(I32="Unknown","Unknown",MONTH(I32)) -> 4 | M32: =IF(I32="Unknown","Unknown",WEEKDAY(I32)) -> 1 | N32: =NOW() -> 46090.857 | O32: 4 | P32: Male | Q32: user125@example.com
A33: EMP1073 | B33: JohnDoe | C33: John | D33: Doe | E33: =TRIM(B33) -> JohnDoe | F33: Sales | G33: India | H33: 91101 | I33: 42519 | J33: =IF(I33="Unknown","Unknown",DATEDIF(I33,TODAY(),"Y")) -> 9 | K33: =IF(I33="Unknown","Unknown",YEAR(I33)) -> 2016 | L33: =IF(I33="Unknown","Unknown",MONTH(I33)) -> 5 | M33: =IF(I33="Unknown","Unknown",WEEKDAY(I33)) -> 1 | N33: =NOW() -> 46090.857 | O33: 4 | P33: Female | Q33: user71@example.com
A34: EMP1084 | B34: JohnDoe | C34: John | D34: Doe | E34: =TRIM(B34) -> JohnDoe | F34: Marketing | G34: India | H34: 44682 | I34: 42596 | J34: =IF(I34="Unknown","Unknown",DATEDIF(I34,TODAY(),"Y")) -> 9 | K34: =IF(I34="Unknown","Unknown",YEAR(I34)) -> 2016 | L34: =IF(I34="Unknown","Unknown",MONTH(I34)) -> 8 | M34: =IF(I34="Unknown","Unknown",WEEKDAY(I34)) -> 1 | N34: =NOW() -> 46090.857 | O34: 4 | P34: Female | Q34: user47@example.com
A35: EMP1086 | B35: ChrisLee | C35: Chris | D35: Lee | E35: =TRIM(B35) -> ChrisLee | F35: IT | G35: India | H35: 33483 | I35: 42610 | J35: =IF(I35="Unknown","Unknown",DATEDIF(I35,TODAY(),"Y")) -> 9 | K35: =IF(I35="Unknown","Unknown",YEAR(I35)) -> 2016 | L35: =IF(I35="Unknown","Unknown",MONTH(I35)) -> 8 | M35: =IF(I35="Unknown","Unknown",WEEKDAY(I35)) -> 1 | N35: =NOW() -> 46090.857 | O35: 4 | P35: Male | Q35: user177@example.com
A36: EMP1087 | B36: SamWilson | C36: Sam | D36: Wilson | E36: =TRIM(B36) -> SamWilson | F36: HR | G36: Germany | H36: 55303 | I36: 42617 | J36: =IF(I36="Unknown","Unknown",DATEDIF(I36,TODAY(),"Y")) -> 9 | K36: =IF(I36="Unknown","Unknown",YEAR(I36)) -> 2016 | L36: =IF(I36="Unknown","Unknown",MONTH(I36)) -> 9 | M36: =IF(I36="Unknown","Unknown",WEEKDAY(I36)) -> 1 | N36: =NOW() -> 46090.857 | O36: 4 | P36: Male | Q36: user149@example.com
A37: EMP1093 | B37: AliceBrown | C37: Alice | D37: Brown | E37: =TRIM(B37) -> AliceBrown | F37: Unknown | G37: USA | H37: 76238 | I37: 42659 | J37: =IF(I37="Unknown","Unknown",DATEDIF(I37,TODAY(),"Y")) -> 9 | K37: =IF(I37="Unknown","Unknown",YEAR(I37)) -> 2016 | L37: =IF(I37="Unknown","Unknown",MONTH(I37)) -> 10 | M37: =IF(I37="Unknown","Unknown",WEEKDAY(I37)) -> 1 | N37: =NOW() -> 46090.857 | O37: 4 | P37: Male | Q37: user102@example.com
A38: EMP1099 | B38: EveAdams | C38: Eve | D38: Adams | E38: =TRIM(B38) -> EveAdams | F38: Marketing | G38: USA | H38: 70096 | I38: 42701 | J38: =IF(I38="Unknown","Unknown",DATEDIF(I38,TODAY(),"Y")) -> 9 | K38: =IF(I38="Unknown","Unknown",YEAR(I38)) -> 2016 | L38: =IF(I38="Unknown","Unknown",MONTH(I38)) -> 11 | M38: =IF(I38="Unknown","Unknown",WEEKDAY(I38)) -> 1 | N38: =NOW() -> 46090.857 | O38: 4 | P38: Male | Q38: user76@example.com
A39: EMP1114 | B39: EveAdams | C39: Eve | D39: Adams | E39: =TRIM(B39) -> EveAdams | F39: Marketing | G39: UK | H39: 44627 | I39: 42806 | J39: =IF(I39="Unknown","Unknown",DATEDIF(I39,TODAY(),"Y")) -> 8 | K39: =IF(I39="Unknown","Unknown",YEAR(I39)) -> 2017 | L39: =IF(I39="Unknown","Unknown",MONTH(I39)) -> 3 | M39: =IF(I39="Unknown","Unknown",WEEKDAY(I39)) -> 1 | N39: =NOW() -> 46090.857 | O39: 4 | P39: Unknown | Q39: user97@example.com
A40: EMP1115 | B40: BobJohnson | C40: Bob | D40: Johnson | E40: =TRIM(B40) -> BobJohnson | F40: HR | G40: Germany | H40: 92343 | I40: 42813 | J40: =IF(I40="Unknown","Unknown",DATEDIF(I40,TODAY(),"Y")) -> 8 | K40: =IF(I40="Unknown","Unknown",YEAR(I40)) -> 2017 | L40: =IF(I40="Unknown","Unknown",MONTH(I40)) -> 3 | M40: =IF(I40="Unknown","Unknown",WEEKDAY(I40)) -> 1 | N40: =NOW() -> 46090.857 | O40: 4 | P40: Female | Q40: user149@example.com
...

Sheet Vlookup
A1: EmployeeID | B1: Name | C1: FirstName | D1: LastName | E1: CleanedName | F1: Department | G1: Country | H1: Salary | I1: Date | J1: Experience | K1: Joining Year | L1: Joining month | M1: Joining weekday | N1: Current_Date_Time | O1: PerformanceRating | P1: Gender | Q1: Email
A2: EMP1011 | B2: =VLOOKUP($A2,Employee_Cleaned!$A$2:$Q$151,2,FALSE) -> SamWilson | C2: =VLOOKUP($A2,Employee_Cleaned!$A$2:$Q$151,3,FALSE) -> Sam | D2: =VLOOKUP($A2,Employee_Cleaned!$A$2:$Q$151,4,FALSE) -> Wilson | E2: =VLOOKUP($A2,Employee_Cleaned!$A$2:$Q$151,5,FALSE) -> SamWilson | F2: =VLOOKUP($A2,Employee_Cleaned!$A$2:$Q$151,6,FALSE) -> IT | G2: =VLOOKUP($A2,Employee_Cleaned!$A$2:$Q$151,7,FALSE) -> USA | H2: =VLOOKUP($A2,Employee_Cleaned!$A$2:$Q$151,8,FALSE) -> 91180 | I2: =VLOOKUP($A2,Employee_Cleaned!$A$2:$Q$151,9,FALSE) -> 42085 | J2: =VLOOKUP($A2,Employee_Cleaned!$A$2:$Q$151,10,FALSE) -> 10 | K2: =VLOOKUP($A2,Employee_Cleaned!$A$2:$Q$151,11,FALSE) -> 2015 | L2: =VLOOKUP($A2,Employee_Cleaned!$A$2:$Q$151,12,FALSE) -> 3 | M2: =VLOOKUP($A2,Employee_Cleaned!$A$2:$Q$151,13,FALSE) -> 1 | N2: =VLOOKUP($A2,Employee_Cleaned!$A$2:$Q$151,14,FALSE) -> 46090.857 | O2: =VLOOKUP($A2,Employee_Cleaned!$A$2:$Q$151,15,FALSE) -> 5 | P2: =VLOOKUP($A2,Employee_Cleaned!$A$2:$Q$151,16,FALSE) -> Male | Q2: =VLOOKUP($A2,Employee_Cleaned!$A$2:$Q$151,17,FALSE) -> user1@example.com
A3: EMP1012 | B3: =VLOOKUP($A3,Employee_Cleaned!$A$2:$Q$151,2,FALSE) -> BobJohnson | C3: =VLOOKUP($A3,Employee_Cleaned!$A$2:$Q$151,3,FALSE) -> Bob | D3: =VLOOKUP($A3,Employee_Cleaned!$A$2:$Q$151,4,FALSE) -> Johnson | E3: =VLOOKUP($A3,Employee_Cleaned!$A$2:$Q$151,5,FALSE) -> BobJohnson | F3: =VLOOKUP($A3,Employee_Cleaned!$A$2:$Q$151,6,FALSE) -> Sales | G3: =VLOOKUP($A3,Employee_Cleaned!$A$2:$Q$151,7,FALSE) -> Unknown | H3: =VLOOKUP($A3,Employee_Cleaned!$A$2:$Q$151,8,FALSE) -> 96418 | I3: =VLOOKUP($A3,Employee_Cleaned!$A$2:$Q$151,9,FALSE) -> 42092 | J3: =VLOOKUP($A3,Employee_Cleaned!$A$2:$Q$151,10,FALSE) -> 10 | K3: =VLOOKUP($A3,Employee_Cleaned!$A$2:$Q$151,11,FALSE) -> 2015 | L3: =VLOOKUP($A3,Employee_Cleaned!$A$2:$Q$151,12,FALSE) -> 3 | M3: =VLOOKUP($A3,Employee_Cleaned!$A$2:$Q$151,13,FALSE) -> 1 | N3: =VLOOKUP($A3,Employee_Cleaned!$A$2:$Q$151,14,FALSE) -> 46090.857 | O3: =VLOOKUP($A3,Employee_Cleaned!$A$2:$Q$151,10,FALSE) -> 10 | P3: =VLOOKUP($A3,Employee_Cleaned!$A$2:$Q$151,16,FALSE) -> Male | Q3: =VLOOKUP($A3,Employee_Cleaned!$A$2:$Q$151,17,FALSE) -> user106@example.com
A4: EMP1019 | B4: =VLOOKUP($A4,Employee_Cleaned!$A$2:$Q$151,2,FALSE) -> EveAdams | C4: =VLOOKUP($A4,Employee_Cleaned!$A$2:$Q$151,3,FALSE) -> Eve | D4: =VLOOKUP($A4,Employee_Cleaned!$A$2:$Q$151,4,FALSE) -> Adams | E4: =VLOOKUP($A4,Employee_Cleaned!$A$2:$Q$151,5,FALSE) -> EveAdams | F4: =VLOOKUP($A4,Employee_Cleaned!$A$2:$Q$151,6,FALSE) -> Unknown | G4: =VLOOKUP($A4,Employee_Cleaned!$A$2:$Q$151,7,FALSE) -> India | H4: =VLOOKUP($A4,Employee_Cleaned!$A$2:$Q$151,8,FALSE) -> 67531 | I4: =VLOOKUP($A4,Employee_Cleaned!$A$2:$Q$151,9,FALSE) -> 42141 | J4: =VLOOKUP($A4,Employee_Cleaned!$A$2:$Q$151,10,FALSE) -> 10 | K4: =VLOOKUP($A4,Employee_Cleaned!$A$2:$Q$151,11,FALSE) -> 2015 | L4: =VLOOKUP($A4,Employee_Cleaned!$A$2:$Q$151,12,FALSE) -> 5 | M4: =VLOOKUP($A4,Employee_Cleaned!$A$2:$Q$151,13,FALSE) -> 1 | N4: =VLOOKUP($A4,Employee_Cleaned!$A$2:$Q$151,14,FALSE) -> 46090.857 | O4: =VLOOKUP($A4,Employee_Cleaned!$A$2:$Q$151,10,FALSE) -> 10 | P4: =VLOOKUP($A4,Employee_Cleaned!$A$2:$Q$151,16,FALSE) -> Female | Q4: =VLOOKUP($A4,Employee_Cleaned!$A$2:$Q$151,17,FALSE) -> user151@example.com
A5: EMP1022 | B5: =VLOOKUP($A5,Employee_Cleaned!$A$2:$Q$151,2,FALSE) -> EveAdams | C5: =VLOOKUP($A5,Employee_Cleaned!$A$2:$Q$151,3,FALSE) -> Eve | D5: =VLOOKUP($A5,Employee_Cleaned!$A$2:$Q$151,4,FALSE) -> Adams | E5: =VLOOKUP($A5,Employee_Cleaned!$A$2:$Q$151,5,FALSE) -> EveAdams | F5: =VLOOKUP($A5,Employee_Cleaned!$A$2:$Q$151,6,FALSE) -> Finance | G5: =VLOOKUP($A5,Employee_Cleaned!$A$2:$Q$151,7,FALSE) -> India | H5: =VLOOKUP($A5,Employee_Cleaned!$A$2:$Q$151,8,FALSE) -> 38333 | I5: =VLOOKUP($A5,Employee_Cleaned!$A$2:$Q$151,9,FALSE) -> 42162 | J5: =VLOOKUP($A5,Employee_Cleaned!$A$2:$Q$151,10,FALSE) -> 10 | K5: =VLOOKUP($A5,Employee_Cleaned!$A$2:$Q$151,11,FALSE) -> 2015 | L5: =VLOOKUP($A5,Employee_Cleaned!$A$2:$Q$151,12,FALSE) -> 6 | M5: =VLOOKUP($A5,Employee_Cleaned!$A$2:$Q$151,13,FALSE) -> 1 | N5: =VLOOKUP($A5,Employee_Cleaned!$A$2:$Q$151,14,FALSE) -> 46090.857 | O5: =VLOOKUP($A5,Employee_Cleaned!$A$2:$Q$151,10,FALSE) -> 10 | P5: =VLOOKUP($A5,Employee_Cleaned!$A$2:$Q$151,16,FALSE) -> Unknown | Q5: =VLOOKUP($A5,Employee_Cleaned!$A$2:$Q$151,17,FALSE) -> user128@example.com
A6: EMP1029 | B6: =VLOOKUP($A6,Employee_Cleaned!$A$2:$Q$151,2,FALSE) -> BobJohnson | C6: =VLOOKUP($A6,Employee_Cleaned!$A$2:$Q$151,3,FALSE) -> Bob | D6: =VLOOKUP($A6,Employee_Cleaned!$A$2:$Q$151,4,FALSE) -> Johnson | E6: =VLOOKUP($A6,Employee_Cleaned!$A$2:$Q$151,5,FALSE) -> BobJohnson | F6: =VLOOKUP($A6,Employee_Cleaned!$A$2:$Q$151,6,FALSE) -> Marketing | G6: =VLOOKUP($A6,Employee_Cleaned!$A$2:$Q$151,7,FALSE) -> UK | H6: =VLOOKUP($A6,Employee_Cleaned!$A$2:$Q$151,8,FALSE) -> 92959 | I6: =VLOOKUP($A6,Employee_Cleaned!$A$2:$Q$151,9,FALSE) -> 42211 | J6: =VLOOKUP($A6,Employee_Cleaned!$A$2:$Q$151,10,FALSE) -> 10 | K6: =VLOOKUP($A6,Employee_Cleaned!$A$2:$Q$151,11,FALSE) -> 2015 | L6: =VLOOKUP($A6,Employee_Cleaned!$A$2:$Q$151,12,FALSE) -> 7 | M6: =VLOOKUP($A6,Employee_Cleaned!$A$2:$Q$151,13,FALSE) -> 1 | N6: =VLOOKUP($A6,Employee_Cleaned!$A$2:$Q$151,14,FALSE) -> 46090.857 | O6: =VLOOKUP($A6,Employee_Cleaned!$A$2:$Q$151,10,FALSE) -> 10 | P6: =VLOOKUP($A6,Employee_Cleaned!$A$2:$Q$151,16,FALSE) -> Unknown | Q6: =VLOOKUP($A6,Employee_Cleaned!$A$2:$Q$151,17,FALSE) -> user83@example.com
A7: EMP1038 | B7: =VLOOKUP($A7,Employee_Cleaned!$A$2:$Q$151,2,FALSE) -> JohnDoe | C7: =VLOOKUP($A7,Employee_Cleaned!$A$2:$Q$151,3,FALSE) -> John | D7: =VLOOKUP($A7,Employee_Cleaned!$A$2:$Q$151,4,FALSE) -> Doe | E7: =VLOOKUP($A7,Employee_Cleaned!$A$2:$Q$151,5,FALSE) -> JohnDoe | F7: =VLOOKUP($A7,Employee_Cleaned!$A$2:$Q$151,6,FALSE) -> Marketing | G7: =VLOOKUP($A7,Employee_Cleaned!$A$2:$Q$151,7,FALSE) -> UK | H7: =VLOOKUP($A7,Employee_Cleaned!$A$2:$Q$151,8,FALSE) -> 52093 | I7: =VLOOKUP($A7,Employee_Cleaned!$A$2:$Q$151,9,FALSE) -> 42274 | J7: =VLOOKUP($A7,Employee_Cleaned!$A$2:$Q$151,10,FALSE) -> 10 | K7: =VLOOKUP($A7,Employee_Cleaned!$A$2:$Q$151,11,FALSE) -> 2015 | L7: =VLOOKUP($A7,Employee_Cleaned!$A$2:$Q$151,12,FALSE) -> 9 | M7: =VLOOKUP($A7,Employee_Cleaned!$A$2:$Q$151,13,FALSE) -> 1 | N7: =VLOOKUP($A7,Employee_Cleaned!$A$2:$Q$151,14,FALSE) -> 46090.857 | O7: =VLOOKUP($A7,Employee_Cleaned!$A$2:$Q$151,10,FALSE) -> 10 | P7: =VLOOKUP($A7,Employee_Cleaned!$A$2:$Q$151,16,FALSE) -> Unknown | Q7: =VLOOKUP($A7,Employee_Cleaned!$A$2:$Q$151,17,FALSE) -> user154@example.com
A8: EMP1049 | B8: =VLOOKUP($A8,Employee_Cleaned!$A$2:$Q$151,2,FALSE) -> EveAdams | C8: =VLOOKUP($A8,Employee_Cleaned!$A$2:$Q$151,3,FALSE) -> Eve | D8: =VLOOKUP($A8,Employee_Cleaned!$A$2:$Q$151,4,FALSE) -> Adams | E8: =VLOOKUP($A8,Employee_Cleaned!$A$2:$Q$151,5,FALSE) -> EveAdams | F8: =VLOOKUP($A8,Employee_Cleaned!$A$2:$Q$151,6,FALSE) -> HR | G8: =VLOOKUP($A8,Employee_Cleaned!$A$2:$Q$151,7,FALSE) -> Germany | H8: =VLOOKUP($A8,Employee_Cleaned!$A$2:$Q$151,8,FALSE) -> 78720 | I8: =VLOOKUP($A8,Employee_Cleaned!$A$2:$Q$151,9,FALSE) -> 42351 | J8: =VLOOKUP($A8,Employee_Cleaned!$A$2:$Q$151,10,FALSE) -> 10 | K8: =VLOOKUP($A8,Employee_Cleaned!$A$2:$Q$151,11,FALSE) -> 2015 | L8: =VLOOKUP($A8,Employee_Cleaned!$A$2:$Q$151,12,FALSE) -> 12 | M8: =VLOOKUP($A8,Employee_Cleaned!$A$2:$Q$151,13,FALSE) -> 1 | N8: =VLOOKUP($A8,Employee_Cleaned!$A$2:$Q$151,14,FALSE) -> 46090.857 | O8: =VLOOKUP($A8,Employee_Cleaned!$A$2:$Q$151,10,FALSE) -> 10 | P8: =VLOOKUP($A8,Employee_Cleaned!$A$2:$Q$151,16,FALSE) -> Female | Q8: =VLOOKUP($A8,Employee_Cleaned!$A$2:$Q$151,17,FALSE) -> user89@example.com
A9: EMP1051 | B9: =VLOOKUP($A9,Employee_Cleaned!$A$2:$Q$151,2,FALSE) -> SamWilson | C9: =VLOOKUP($A9,Employee_Cleaned!$A$2:$Q$151,3,FALSE) -> Sam | D9: =VLOOKUP($A9,Employee_Cleaned!$A$2:$Q$151,4,FALSE) -> Wilson | E9: =VLOOKUP($A9,Employee_Cleaned!$A$2:$Q$151,5,FALSE) -> SamWilson | F9: =VLOOKUP($A9,Employee_Cleaned!$A$2:$Q$151,6,FALSE) -> Sales | G9: =VLOOKUP($A9,Employee_Cleaned!$A$2:$Q$151,7,FALSE) -> India | H9: =VLOOKUP($A9,Employee_Cleaned!$A$2:$Q$151,8,FALSE) -> 39423 | I9: =VLOOKUP($A9,Employee_Cleaned!$A$2:$Q$151,9,FALSE) -> 42365 | J9: =VLOOKUP($A9,Employee_Cleaned!$A$2:$Q$151,10,FALSE) -> 10 | K9: =VLOOKUP($A9,Employee_Cleaned!$A$2:$Q$151,11,FALSE) -> 2015 | L9: =VLOOKUP($A9,Employee_Cleaned!$A$2:$Q$151,12,FALSE) -> 12 | M9: =VLOOKUP($A9,Employee_Cleaned!$A$2:$Q$151,13,FALSE) -> 1 | N9: =VLOOKUP($A9,Employee_Cleaned!$A$2:$Q$151,14,FALSE) -> 46090.857 | O9: =VLOOKUP($A9,Employee_Cleaned!$A$2:$Q$151,10,FALSE) -> 10 | P9: =VLOOKUP($A9,Employee_Cleaned!$A$2:$Q$151,16,FALSE) -> Unknown | Q9: =VLOOKUP($A9,Employee_Cleaned!$A$2:$Q$151,17,FALSE) -> user59@example.com
A10: EMP1054 | B10: =VLOOKUP($A10,Employee_Cleaned!$A$2:$Q$151,2,FALSE) -> BobJohnson | C10: =VLOOKUP($A10,Employee_Cleaned!$A$2:$Q$151,3,FALSE) -> Bob | D10: =VLOOKUP($A10,Employee_Cleaned!$A$2:$Q$151,4,FALSE) -> Johnson | E10: =VLOOKUP($A10,Employee_Cleaned!$A$2:$Q$151,5,FALSE) -> BobJohnson | F10: =VLOOKUP($A10,Employee_Cleaned!$A$2:$Q$151,6,FALSE) -> Marketing | G10: =VLOOKUP($A10,Employee_Cleaned!$A$2:$Q$151,7,FALSE) -> UK | H10: =VLOOKUP($A10,Employee_Cleaned!$A$2:$Q$151,8,FALSE) -> 75633 | I10: =VLOOKUP($A10,Employee_Cleaned!$A$2:$Q$151,9,FALSE) -> 42386 | J10: =VLOOKUP($A10,Employee_Cleaned!$A$2:$Q$151,10,FALSE) -> 10 | K10: =VLOOKUP($A10,Employee_Cleaned!$A$2:$Q$151,11,FALSE) -> 2016 | L10: =VLOOKUP($A10,Employee_Cleaned!$A$2:$Q$151,12,FALSE) -> 1 | M10: =VLOOKUP($A10,Employee_Cleaned!$A$2:$Q$151,13,FALSE) -> 1 | N10: =VLOOKUP($A10,Employee_Cleaned!$A$2:$Q$151,14,FALSE) -> 46090.857 | O10: =VLOOKUP($A10,Employee_Cleaned!$A$2:$Q$151,10,FALSE) -> 10 | P10: =VLOOKUP($A10,Employee_Cleaned!$A$2:$Q$151,16,FALSE) -> Other | Q10: =VLOOKUP($A10,Employee_Cleaned!$A$2:$Q$151,17,FALSE) -> user92@example.com
A11: EMP1055 | B11: =VLOOKUP($A11,Employee_Cleaned!$A$2:$Q$151,2,FALSE) -> ChrisLee | C11: =VLOOKUP($A11,Employee_Cleaned!$A$2:$Q$151,3,FALSE) -> Chris | D11: =VLOOKUP($A11,Employee_Cleaned!$A$2:$Q$151,4,FALSE) -> Lee | E11: =VLOOKUP($A11,Employee_Cleaned!$A$2:$Q$151,5,FALSE) -> ChrisLee | F11: =VLOOKUP($A11,Employee_Cleaned!$A$2:$Q$151,6,FALSE) -> Unknown | G11: =VLOOKUP($A11,Employee_Cleaned!$A$2:$Q$151,7,FALSE) -> USA | H11: =VLOOKUP($A11,Employee_Cleaned!$A$2:$Q$151,8,FALSE) -> 74815 | I11: =VLOOKUP($A11,Employee_Cleaned!$A$2:$Q$151,9,FALSE) -> 42393 | J11: =VLOOKUP($A11,Employee_Cleaned!$A$2:$Q$151,10,FALSE) -> 10 | K11: =VLOOKUP($A11,Employee_Cleaned!$A$2:$Q$151,11,FALSE) -> 2016 | L11: =VLOOKUP($A11,Employee_Cleaned!$A$2:$Q$151,12,FALSE) -> 1 | M11: =VLOOKUP($A11,Employee_Cleaned!$A$2:$Q$151,13,FALSE) -> 1 | N11: =VLOOKUP($A11,Employee_Cleaned!$A$2:$Q$151,14,FALSE) -> 46090.857 | O11: =VLOOKUP($A11,Employee_Cleaned!$A$2:$Q$151,10,FALSE) -> 10 | P11: =VLOOKUP($A11,Employee_Cleaned!$A$2:$Q$151,16,FALSE) -> Female | Q11: =VLOOKUP($A11,Employee_Cleaned!$A$2:$Q$151,17,FALSE) -> user50@example.com
A12: EMP1058 | B12: =VLOOKUP($A12,Employee_Cleaned!$A$2:$Q$151,2,FALSE) -> SamWilson | C12: =VLOOKUP($A12,Employee_Cleaned!$A$2:$Q$151,3,FALSE) -> Sam | D12: =VLOOKUP($A12,Employee_Cleaned!$A$2:$Q$151,4,FALSE) -> Wilson | E12: =VLOOKUP($A12,Employee_Cleaned!$A$2:$Q$151,5,FALSE) -> SamWilson | F12: =VLOOKUP($A12,Employee_Cleaned!$A$2:$Q$151,6,FALSE) -> Marketing | G12: =VLOOKUP($A12,Employee_Cleaned!$A$2:$Q$151,7,FALSE) -> Unknown | H12: =VLOOKUP($A12,Employee_Cleaned!$A$2:$Q$151,8,FALSE) -> 84924 | I12: =VLOOKUP($A12,Employee_Cleaned!$A$2:$Q$151,9,FALSE) -> 42414 | J12: =VLOOKUP($A12,Employee_Cleaned!$A$2:$Q$151,10,FALSE) -> 10 | K12: =VLOOKUP($A12,Employee_Cleaned!$A$2:$Q$151,11,FALSE) -> 2016 | L12: =VLOOKUP($A12,Employee_Cleaned!$A$2:$Q$151,12,FALSE) -> 2 | M12: =VLOOKUP($A12,Employee_Cleaned!$A$2:$Q$151,13,FALSE) -> 1 | N12: =VLOOKUP($A12,Employee_Cleaned!$A$2:$Q$151,14,FALSE) -> 46090.857 | O12: =VLOOKUP($A12,Employee_Cleaned!$A$2:$Q$151,10,FALSE) -> 10 | P12: =VLOOKUP($A12,Employee_Cleaned!$A$2:$Q$151,16,FALSE) -> Male | Q12: =VLOOKUP($A12,Employee_Cleaned!$A$2:$Q$151,17,FALSE) -> user150@example.com
A13: EMP1060 | B13: =VLOOKUP($A13,Employee_Cleaned!$A$2:$Q$151,2,FALSE) -> Unknown | C13: =VLOOKUP($A13,Employee_Cleaned!$A$2:$Q$151,3,FALSE) -> Unknown | D13: =VLOOKUP($A13,Employee_Cleaned!$A$2:$Q$151,4,FALSE) -> Unknown | E13: =VLOOKUP($A13,Employee_Cleaned!$A$2:$Q$151,5,FALSE) -> Unknown | F13: =VLOOKUP($A13,Employee_Cleaned!$A$2:$Q$151,6,FALSE) -> Marketing | G13: =VLOOKUP($A13,Employee_Cleaned!$A$2:$Q$151,7,FALSE) -> Germany | H13: =VLOOKUP($A13,Employee_Cleaned!$A$2:$Q$151,8,FALSE) -> 66281 | I13: =VLOOKUP($A13,Employee_Cleaned!$A$2:$Q$151,9,FALSE) -> Unknown | J13: =VLOOKUP($A13,Employee_Cleaned!$A$2:$Q$151,10,FALSE) -> Unknown | K13: =VLOOKUP($A13,Employee_Cleaned!$A$2:$Q$151,11,FALSE) -> Unknown | L13: =VLOOKUP($A13,Employee_Cleaned!$A$2:$Q$151,12,FALSE) -> Unknown | M13: =VLOOKUP($A13,Employee_Cleaned!$A$2:$Q$151,13,FALSE) -> Unknown | N13: =VLOOKUP($A13,Employee_Cleaned!$A$2:$Q$151,14,FALSE) -> 46090.857 | O13: =VLOOKUP($A13,Employee_Cleaned!$A$2:$Q$151,10,FALSE) -> Unknown | P13: =VLOOKUP($A13,Employee_Cleaned!$A$2:$Q$151,16,FALSE) -> Unknown | Q13: =VLOOKUP($A13,Employee_Cleaned!$A$2:$Q$151,17,FALSE) -> user112@example.com
A14: EMP1062 | B14: =VLOOKUP($A14,Employee_Cleaned!$A$2:$Q$151,2,FALSE) -> ChrisLee | C14: =VLOOKUP($A14,Employee_Cleaned!$A$2:$Q$151,3,FALSE) -> Chris | D14: =VLOOKUP($A14,Employee_Cleaned!$A$2:$Q$151,4,FALSE) -> Lee | E14: =VLOOKUP($A14,Employee_Cleaned!$A$2:$Q$151,5,FALSE) -> ChrisLee | F14: =VLOOKUP($A14,Employee_Cleaned!$A$2:$Q$151,6,FALSE) -> IT | G14: =VLOOKUP($A14,Employee_Cleaned!$A$2:$Q$151,7,FALSE) -> UK | H14: =VLOOKUP($A14,Employee_Cleaned!$A$2:$Q$151,8,FALSE) -> 97981 | I14: =VLOOKUP($A14,Employee_Cleaned!$A$2:$Q$151,9,FALSE) -> 42442 | J14: =VLOOKUP($A14,Employee_Cleaned!$A$2:$Q$151,10,FALSE) -> 9 | K14: =VLOOKUP($A14,Employee_Cleaned!$A$2:$Q$151,11,FALSE) -> 2016 | L14: =VLOOKUP($A14,Employee_Cleaned!$A$2:$Q$151,12,FALSE) -> 3 | M14: =VLOOKUP($A14,Employee_Cleaned!$A$2:$Q$151,13,FALSE) -> 1 | N14: =VLOOKUP($A14,Employee_Cleaned!$A$2:$Q$151,14,FALSE) -> 46090.857 | O14: =VLOOKUP($A14,Employee_Cleaned!$A$2:$Q$151,10,FALSE) -> 9 | P14: =VLOOKUP($A14,Employee_Cleaned!$A$2:$Q$151,16,FALSE) -> Female | Q14: =VLOOKUP($A14,Employee_Cleaned!$A$2:$Q$151,17,FALSE) -> user71@example.com
... A25: EMP1145 | B25: =VLOOKUP($A25,Employee_Cleaned!$A$2:$Q$151,2,FALSE) -> SamWilson | C25: =VLOOKUP($A25,Employee_Cleaned!$A$2:$Q$151,3,FALSE) -> Sam | D25: =VLOOKUP($A25,Employee_Cleaned!$A$2:$Q$151,4,FALSE) -> Wilson | E25: =VLOOKUP($A25,Employee_Cleaned!$A$2:$Q$151,5,FALSE) -> SamWilson | F25: =VLOOKUP($A25,Employee_Cleaned!$A$2:$Q$151,6,FALSE) -> Sales | G25: =VLOOKUP($A25,Employee_Cleaned!$A$2:$Q$151,7,FALSE) -> Australia | H25: =VLOOKUP($A25,Employee_Cleaned!$A$2:$Q$151,8,FALSE) -> 35627 | I25: =VLOOKUP($A25,Employee_Cleaned!$A$2:$Q$151,9,FALSE) -> 43023 | J25: =VLOOKUP($A25,Employee_Cleaned!$A$2:$Q$151,10,FALSE) -> 8 | K25: =VLOOKUP($A25,Employee_Cleaned!$A$2:$Q$151,11,FALSE) -> 2017 | L25: =VLOOKUP($A25,Employee_Cleaned!$A$2:$Q$151,12,FALSE) -> 10 | M25: =VLOOKUP($A25,Employee_Cleaned!$A$2:$Q$151,13,FALSE) -> 1 | N25: =VLOOKUP($A25,Employee_Cleaned!$A$2:$Q$151,14,FALSE) -> 46090.857 | O25: =VLOOKUP($A25,Employee_Cleaned!$A$2:$Q$151,10,FALSE) -> 8 | P25: =VLOOKUP($A25,Employee_Cleaned!$A$2:$Q$151,16,FALSE) -> Female | Q25: =VLOOKUP($A25,Employee_Cleaned!$A$2:$Q$151,17,FALSE) -> user188@example.com
A26: EMP1149 | B26: =VLOOKUP($A26,Employee_Cleaned!$A$2:$Q$151,2,FALSE) -> SamWilson | C26: =VLOOKUP($A26,Employee_Cleaned!$A$2:$Q$151,3,FALSE) -> Sam | D26: =VLOOKUP($A26,Employee_Cleaned!$A$2:$Q$151,4,FALSE) -> Wilson | E26: =VLOOKUP($A26,Employee_Cleaned!$A$2:$Q$151,5,FALSE) -> SamWilson | F26: =VLOOKUP($A26,Employee_Cleaned!$A$2:$Q$151,6,FALSE) -> Marketing | G26: _ | H26: =VLOOKUP($A26,Employee_Cleaned!$A$2:$Q$151,8,FALSE) -> 98475 | I26: =VLOOKUP($A26,Employee_Cleaned!$A$2:$Q$151,9,FALSE) -> 43051 | J26: =VLOOKUP($A26,Employee_Cleaned!$A$2:$Q$151,10,FALSE) -> 8 | K26: =VLOOKUP($A26,Employee_Cleaned!$A$2:$Q$151,11,FALSE) -> 2017 | L26: =VLOOKUP($A26,Employee_Cleaned!$A$2:$Q$151,12,FALSE) -> 11 | M26: =VLOOKUP($A26,Employee_Cleaned!$A$2:$Q$151,13,FALSE) -> 1 | N26: =VLOOKUP($A26,Employee_Cleaned!$A$2:$Q$151,14,FALSE) -> 46090.857 | O26: =VLOOKUP($A26,Employee_Cleaned!$A$2:$Q$151,10,FALSE) -> 8 | P26: =VLOOKUP($A26,Employee_Cleaned!$A$2:$Q$151,16,FALSE) -> Other | Q26: =VLOOKUP($A26,Employee_Cleaned!$A$2:$Q$151,17,FALSE) -> user30@example.com

Sheet Index&Match
A1: EmployeeID | B1: Name | C1: FirstName | D1: LastName | E1: CleanedName | F1: Department | G1: Country | H1: Salary | I1: Date | J1: Experience | K1: Joining Year | L1: Joining month | M1: Joining weekday | N1: Current_Date_Time | O1: PerformanceRating | P1: Gender | Q1: Email
A2: EMP1011 | B2: =INDEX(Employee_Cleaned!$B$2:$B$151,MATCH(A2,Employee_Cleaned!$A$2:$A$151,0)) -> SamWilson
A3: EMP1012 | B3: =INDEX(Employee_Cleaned!$B$2:$B$151,MATCH(A3,Employee_Cleaned!$A$2:$A$151,0)) -> BobJohnson
A4: EMP1019 | B4: =INDEX(Employee_Cleaned!$B$2:$B$151,MATCH(A4,Employee_Cleaned!$A$2:$A$151,0)) -> EveAdams
A5: EMP1022 | B5: =INDEX(Employee_Cleaned!$B$2:$B$151,MATCH(A5,Employee_Cleaned!$A$2:$A$151,0)) -> EveAdams
A6: EMP1029 | B6: =INDEX(Employee_Cleaned!$B$2:$B$151,MATCH(A6,Employee_Cleaned!$A$2:$A$151,0)) -> BobJohnson
A7: EMP1038 | B7: =INDEX(Employee_Cleaned!$B$2:$B$151,MATCH(A7,Employee_Cleaned!$A$2:$A$151,0)) -> JohnDoe
A8: EMP1049 | B8: =INDEX(Employee_Cleaned!$B$2:$B$151,MATCH(A8,Employee_Cleaned!$A$2:$A$151,0)) -> EveAdams
A9: EMP1051 | B9: =INDEX(Employee_Cleaned!$B$2:$B$151,MATCH(A9,Employee_Cleaned!$A$2:$A$151,0)) -> SamWilson
A10: EMP1054 | B10: =INDEX(Employee_Cleaned!$B$2:$B$151,MATCH(A10,Employee_Cleaned!$A$2:$A$151,0)) -> BobJohnson
A11: EMP1055 | B11: =INDEX(Employee_Cleaned!$B$2:$B$151,MATCH(A11,Employee_Cleaned!$A$2:$A$151,0)) -> ChrisLee
A12: EMP1058 | B12: =INDEX(Employee_Cleaned!$B$2:$B$151,MATCH(A12,Employee_Cleaned!$A$2:$A$151,0)) -> SamWilson
A13: EMP1060 | B13: =INDEX(Employee_Cleaned!$B$2:$B$151,MATCH(A13,Employee_Cleaned!$A$2:$A$151,0)) -> Unknown
... A26: EMP1149 | B26: =INDEX(Employee_Cleaned!$B$2:$B$151,MATCH(A26,Employee_Cleaned!$A$2:$A$151,0)) -> SamWilson

Sheet Pivot tables_Chart
A3: Row Labels | B3: Average Salary | C3: Employee Count
A4: Finance | B4: 65666.045 | C4: 22
A5: HR | B5: 67769.833 | C5: 24
A6: IT | B6: 66162.44 | C6: 25
A7: Marketing | B7: 63955.069 | C7: 29
A8: Sales | B8: 67865.692 | C8: 26
A9: Unknown | B9: 66572.708 | C9: 24
A10: Grand Total | B10: 66280.933 | C10: 150

Sheet Pivot Chart
A1: Row Labels | B1: Sum of Salary
A2: Finance | B2: 1444653
A3: HR | B3: 1626476
A4: IT | B4: 1654061
A5: Marketing | B5: 1854697
A6: Sales | B6: 1764508
A7: Unknown | B7: 1597745
A8: (blank)
A9: Grand Total | B9: 9942140

Sheet Report
A1: Day 17 – Charts & Graphs (Part 1)
A2: Practice: Bar, Column, Pie, Line charts.
A3: Task: Visualize key KPIs (such as total sales or average score).
A5: Practiced
A6: Created Bar chart for Average Salary by Department
A7: Created Bar chart for Employee performance by Department
A8: Created Clustered Column Chart for Employee count for Department
